Workbook

Sheet Ensaios
B2: Ensaios no motor CC 775 HANPOSE
B3: Obs: As medições de corrente foram feitas com uma espira de 5 votas no alicate amperimetro
B5: Calculo de Ra (resistência de armadura) | H5: Calculo de La (indutância de armadura) | P5: Calculo das perdas rotacionais | AC5: Calculo de Kt (constante mecanica) | AK5: Comparação entre Ke e Kt | AN5: Máx. Corrente admitida = | AQ5: 20
B6: Medição | C6: V [V] | D6: I (5 espiras) [A] | E6: I (real) [A] | F6: Ra [Ω] | H6: Constante de tempo obtida: | K6: τ = | L6: 600 | N6: 5 | P6: Medição | Q6: V [V] | R6: I (5 espiras) [A] | S6: I (real) [A] | T6: frequência [Hz] | U6: RPM | V6: ω [rad/s] | W6: P_in [W] | X6: P_cu [W] | Y6: P_rot [W] | Z6: T_perdas [Nm] | AC6: Medição | AD6: I (5 espiras) [A] | AE6: I (real) [A] | AF6: Peso [g] | AG6: Força [N] | AH6: Torque [Nm] | AK6: Ke [Vs/rad] | AL6: =L31 -> 0.0095302116 | AN6: Torque máx. fabricante = | AQ6: 0.2
B7: 1 | C7: 1.242 | D7: 42.29 | E7: =D7/5 -> 8.458 | F7: =C7/E7 -> 0.14684323 | H7: Resistêcncia de armadura: | K7: Ra = | L7: =F12 -> 0.15810998 | N7: =N6/L7 -> 31.623557 | P7: 1 | Q7: 1.51 | R7: 3.79 | S7: =R7/5 -> 0.758 | T7: 2272 | U7: =T7*0.6 -> 1363.2 | V7: =(U7*2*PI())/60 -> 142.75397 | W7: =Q7*S7 -> 1.14458 | X7: =S7*S7*$F$12 -> 0.090844304 | Y7: =W7-X7 -> 1.0537357 | Z7: =Y7/V7 -> 0.0073814808 | AC7: 1 | AD7: 0 | AE7: =AD7/5 -> 0 | AF7: 0 | AG7: =AF7*9.80665/1000 -> 0 | AH7: =AG7*23.1/100 -> 0 | AK7: Kt [Nm/A] | AL7: =AK28 -> 0.0097374748 | AN7: Torque máx. calculado = | AQ7: =AQ5*AL7 -> 0.1947495
B8: 2 | C8: 1.371 | D8: 42.21 | E8: =D8/5 -> 8.442 | F8: =C8/E8 -> 0.16240227 | H8: La calculada: | K8: La = | L8: =(L6)*L7 -> 94.86599 | P8: 2 | Q8: 1.983 | R8: 4.09 | S8: =R8/5 -> 0.818 | T8: 3125 | U8: =T8*0.6 -> 1875 | V8: =(U8*2*PI())/60 -> 196.34954 | W8: =Q8*S8 -> 1.622094 | X8: =S8*S8*$F$12 -> 0.10579518 | Y8: =W8-X8 -> 1.5162988 | Z8: =Y8/V8 -> 0.0077224465 | AC8: 2 | AD8: 5.6 | AE8: =AD8/5 -> 1.12 | AF8: 3 | AG8: =AF8*9.80665/1000 -> 0.02941995 | AH8: =AG8*23.1/100 -> 0.0067960085 | AK8: Diferença | AL8: =ABS(AL6-AL7) -> 0.00020726318 | AN8: Diferença = | AQ8: =ABS(AQ6-AQ7) -> 0.0052505035
B9: 3 | C9: 1.335 | D9: 42.35 | E9: =D9/5 -> 8.47 | F9: =C9/E9 -> 0.15761511 | P9: 3 | Q9: 2.494 | R9: 4.23 | S9: =R9/5 -> 0.846 | T9: 4032 | U9: =T9*0.6 -> 2419.2 | V9: =(U9*2*PI())/60 -> 253.33803 | W9: =Q9*S9 -> 2.109924 | X9: =S9*S9*$F$12 -> 0.11316184 | Y9: =W9-X9 -> 1.9967622 | Z9: =Y9/V9 -> 0.0078818097 | AC9: 3 | AD9: 5.7 | AE9: =AD9/5 -> 1.14 | AF9: 4 | AG9: =AF9*9.80665/1000 -> 0.0392266 | AH9: =AG9*23.1/100 -> 0.0090613446 | AK9: Diferença [%] | AL9: =AL8*100 -> 0.020726318
B10: 4 | C10: 0.827 | D10: 24.27 | E10: =D10/5 -> 4.854 | F10: =C10/E10 -> 0.17037495 | P10: 4 | Q10: 3.054 | R10: 4.24 | S10: =R10/5 -> 0.848 | T10: 4902 | U10: =T10*0.6 -> 2941.2 | V10: =(U10*2*PI())/60 -> 308.00174 | W10: =Q10*S10 -> 2.589792 | X10: =S10*S10*$F$12 -> 0.11369752 | Y10: =W10-X10 -> 2.4760945 | Z10: =Y10/V10 -> 0.0080392223 | AC10: 4 | AD10: 6 | AE10: =AD10/5 -> 1.2 | AF10: 5 | AG10: =AF10*9.80665/1000 -> 0.04903325 | AH10: =AG10*23.1/100 -> 0.011326681
B11: 5 | C11: 0.754 | D11: 24.59 | E11: =D11/5 -> 4.918 | F11: =C11/E11 -> 0.15331436 | P11: 5 | Q11: 3.532 | R11: 4.42 | S11: =R11/5 -> 0.884 | T11: 5882 | U11: =T11*0.6 -> 3529.2 | V11: =(U11*2*PI())/60 -> 369.57696 | W11: =Q11*S11 -> 3.122288 | X11: =S11*S11*$F$12 -> 0.12355599 | Y11: =W11-X11 -> 2.998732 | Z11: =Y11/V11 -> 0.0081139582 | AC11: 5 | AD11: 8 | AE11: =AD11/5 -> 1.6 | AF11: 6 | AG11: =AF11*9.80665/1000 -> 0.0588399 | AH11: =AG11*23.1/100 -> 0.013592017
B12: Média = | F12: =SUM(F7:F11)/B11 -> 0.15810998 | P12: 6 | Q12: 4.005 | R12: 4.58 | S12: =R12/5 -> 0.916 | T12: 6579 | U12: =T12*0.6 -> 3947.4 | V12: =(U12*2*PI())/60 -> 413.37076 | W12: =Q12*S12 -> 3.66858 | X12: =S12*S12*$F$12 -> 0.13266313 | Y12: =W12-X12 -> 3.5359169 | Z12: =Y12/V12 -> 0.008553863 | AC12: 6 | AD12: 8.8 | AE12: =AD12/5 -> 1.76 | AF12: 7 | AG12: =AF12*9.80665/1000 -> 0.06864655 | AH12: =AG12*23.1/100 -> 0.015857353
P13: 7 | Q13: 4.501 | R13: 4.69 | S13: =R13/5 -> 0.938 | T13: 7463 | U13: =T13*0.6 -> 4477.8 | V13: =(U13*2*PI())/60 -> 468.91412 | W13: =Q13*S13 -> 4.221938 | X13: =S13*S13*$F$12 -> 0.13911212 | Y13: =W13-X13 -> 4.0828259 | Z13: =Y13/V13 -> 0.00870698 | AC13: 7 | AD13: 9.2 | AE13: =AD13/5 -> 1.84 | AF13: 8 | AG13: =AF13*9.80665/1000 -> 0.0784532 | AH13: =AG13*23.1/100 -> 0.018122689
B14: Calculo de Ke (constante elétrica) | P14: 8 | Q14: 5.012 | R14: 4.85 | S14: =R14/5 -> 0.97 | T14: 8333 | U14: =T14*0.6 -> 4999.8 | V14: =(U14*2*PI())/60 -> 523.57783 | W14: =Q14*S14 -> 4.86164 | X14: =S14*S14*$F$12 -> 0.14876568 | Y14: =W14-X14 -> 4.7128743 | Z14: =Y14/V14 -> 0.009001287 | AC14: 8 | AD14: 10.6 | AE14: =AD14/5 -> 2.12 | AF14: 9 | AG14: =AF14*9.80665/1000 -> 0.08825985 | AH14: =AG14*23.1/100 -> 0.020388025
B15: Medição | C15: E [V] | D15: frequência [Hz] | E15: RPM | F15: rad/s | P15: 9 | Q15: 5.509 | R15: 4.97 | S15: =R15/5 -> 0.994 | T15: 9091 | U15: =T15*0.6 -> 5454.6 | V15: =(U15*2*PI())/60 -> 571.20438 | W15: =Q15*S15 -> 5.475946 | X15: =S15*S15*$F$12 -> 0.15621836 | Y15: =W15-X15 -> 5.3197276 | Z15: =Y15/V15 -> 0.0093131773 | AC15: 9 | AD15: 12.2 | AE15: =AD15/5 -> 2.44 | AF15: 10 | AG15: =AF15*9.80665/1000 -> 0.0980665 | AH15: =AG15*23.1/100 -> 0.022653362
B16: 0 | C16: 0 | D16: 0 | E16: =D16*0.6 -> 0 | F16: =(2*PI()/60)*E16 -> 0 | P16: 10 | Q16: 6.04 | R16: 5.05 | S16: =R16/5 -> 1.01 | T16: 10000 | U16: =T16*0.6 -> 6000 | V16: =(U16*2*PI())/60 -> 628.31853 | W16: =Q16*S16 -> 6.1004 | X16: =S16*S16*$F$12 -> 0.16128799 | Y16: =W16-X16 -> 5.939112 | Z16: =Y16/V16 -> 0.0094523903 | AC16: 10 | AD16: 13.3 | AE16: =AD16/5 -> 2.66 | AF16: 11 | AG16: =AF16*9.80665/1000 -> 0.10787315 | AH16: =AG16*23.1/100 -> 0.024918698
B17: 1 | C17: 0.0131 | D17: 21.74 | E17: =D17*0.6 -> 13.044 | F17: =(2*PI()/60)*E17 -> 1.3659645 | P17: 11 | Q17: 6.51 | R17: 5.2 | S17: =R17/5 -> 1.04 | T17: 10870 | U17: =T17*0.6 -> 6522 | V17: =(U17*2*PI())/60 -> 682.98224 | W17: =Q17*S17 -> 6.7704 | X17: =S17*S17*$F$12 -> 0.17101176 | Y17: =W17-X17 -> 6.5993882 | Z17: =Y17/V17 -> 0.0096626059 | AC17: 11 | AD17: 13.7 | AE17: =AD17/5 -> 2.74 | AF17: 12 | AG17: =AF17*9.80665/1000 -> 0.1176798 | AH17: =AG17*23.1/100 -> 0.027184034
B18: 2 | C18: 0.0139 | D18: 22.81 | E18: =D18*0.6 -> 13.686 | F18: =(2*PI()/60)*E18 -> 1.4331946 | P18: 12 | Q18: 7.05 | R18: 5.26 | S18: =R18/5 -> 1.052 | T18: 11628 | U18: =T18*0.6 -> 6976.8 | V18: =(U18*2*PI())/60 -> 730.60879 | W18: =Q18*S18 -> 7.4166 | X18: =S18*S18*$F$12 -> 0.17498095 | Y18: =W18-X18 -> 7.241619 | Z18: =Y18/V18 -> 0.0099117601 | AC18: 12 | AD18: 15 | AE18: =AD18/5 -> 3 | AF18: 13 | AG18: =AF18*9.80665/1000 -> 0.12748645 | AH18: =AG18*23.1/100 -> 0.02944937
B19: 3 | C19: 0.0185 | D19: 30.9 | E19: =D19*0.6 -> 18.54 | F19: =(2*PI()/60)*E19 -> 1.9415043 | P19: 13 | Q19: 7.52 | R19: 5.6 | S19: =R19/5 -> 1.12 | T19: 12777 | U19: =T19*0.6 -> 7666.2 | V19: =(U19*2*PI())/60 -> 802.80259 | W19: =Q19*S19 -> 8.4224 | X19: =S19*S19*$F$12 -> 0.19833316 | Y19: =W19-X19 -> 8.2240668 | Z19: =Y19/V19 -> 0.010244196 | AC19: 13 | AD19: 16.5 | AE19: =AD19/5 -> 3.3 | AF19: 14 | AG19: =AF19*9.80665/1000 -> 0.1372931 | AH19: =AG19*23.1/100 -> 0.031714706
B20: 4 | C20: 0.0213 | D20: 35.87 | E20: =D20*0.6 -> 21.522 | F20: =(2*PI()/60)*E20 -> 2.2537786 | P20: 14 | Q20: 8.06 | R20: 5.7 | S20: =R20/5 -> 1.14 | T20: 13464 | U20: =T20*0.6 -> 8078.4 | V20: =(U20*2*PI())/60 -> 845.96807 | W20: =Q20*S20 -> 9.1884 | X20: =S20*S20*$F$12 -> 0.20547973 | Y20: =W20-X20 -> 8.9829203 | Z20: =Y20/V20 -> 0.01061851 | AC20: 14 | AD20: 17.9 | AE20: =AD20/5 -> 3.58 | AF20: 15 | AG20: =AF20*9.80665/1000 -> 0.14709975 | AH20: =AG20*23.1/100 -> 0.033980042
B21: 5 | C21: 0.0258 | D21: 42.81 | E21: =D21*0.6 -> 25.686 | F21: =(2*PI()/60)*E21 -> 2.6898316 | P21: 15 | Q21: 8.51 | R21: 5.9 | S21: =R21/5 -> 1.18 | T21: 14560 | U21: =T21*0.6 -> 8736 | V21: =(U21*2*PI())/60 -> 914.83178 | W21: =Q21*S21 -> 10.0418 | X21: =S21*S21*$F$12 -> 0.22015234 | Y21: =W21-X21 -> 9.8216477 | Z21: =Y21/V21 -> 0.010736015 | AC21: 15 | AD21: 20.3 | AE21: =AD21/5 -> 4.06 | AF21: 16 | AG21: =AF21*9.80665/1000 -> 0.1569064 | AH21: =AG21*23.1/100 -> 0.036245378
B22: 6 | C22: 0.0271 | D22: 46.17 | E22: =D22*0.6 -> 27.702 | F22: =(2*PI()/60)*E22 -> 2.9009467 | P22: 16 | Q22: 9.05 | R22: 5.9 | S22: =R22/5 -> 1.18 | T22: 15151 | U22: =T22*0.6 -> 9090.6 | V22: =(U22*2*PI())/60 -> 951.96541 | W22: =Q22*S22 -> 10.679 | X22: =S22*S22*$F$12 -> 0.22015234 | Y22: =W22-X22 -> 10.458848 | Z22: =Y22/V22 -> 0.010986584 | AC22: 16 | AD22: 20.4 | AE22: =AD22/5 -> 4.08 | AF22: 17 | AG22: =AF22*9.80665/1000 -> 0.16671305 | AH22: =AG22*23.1/100 -> 0.038510715
B23: 7 | C23: 0.0372 | D23: 62.03 | E23: =D23*0.6 -> 37.218 | F23: =(2*PI()/60)*E23 -> 3.8974598 | P23: 17 | Q23: 9.49 | R23: 5.9 | S23: =R23/5 -> 1.18 | T23: 15625 | U23: =T23*0.6 -> 9375 | V23: =(U23*2*PI())/60 -> 981.7477 | W23: =Q23*S23 -> 11.1982 | X23: =S23*S23*$F$12 -> 0.22015234 | Y23: =W23-X23 -> 10.978048 | Z23: =Y23/V23 -> 0.011182148 | AC23: 17 | AD23: 21.1 | AE23: =AD23/5 -> 4.22 | AF23: 18 | AG23: =AF23*9.80665/1000 -> 0.1765197 | AH23: =AG23*23.1/100 -> 0.040776051
B24: 8 | C24: 0.0578 | D24: 95.97 | E24: =D24*0.6 -> 57.582 | F24: =(2*PI()/60)*E24 -> 6.0299729 | AC24: 18 | AD24: 21.5 | AE24: =AD24/5 -> 4.3 | AF24: 19 | AG24: =AF24*9.80665/1000 -> 0.18632635 | AH24: =AG24*23.1/100 -> 0.043041387
B25: 9 | C25: 0.0654 | D25: 108.4 | E25: =D25*0.6 -> 65.04 | F25: =(2*PI()/60)*E25 -> 6.8109729 | AC25: 19 | AD25: 22.4 | AE25: =AD25/5 -> 4.48 | AF25: 20 | AG25: =AF25*9.80665/1000 -> 0.196133 | AH25: =AG25*23.1/100 -> 0.045306723
B26: 10 | C26: 0.0838 | D26: 139.6 | E26: =D26*0.6 -> 83.76 | F26: =(2*PI()/60)*E26 -> 8.7713267 | AC26: 20 | AD26: 22.9 | AE26: =AD26/5 -> 4.58 | AF26: 21 | AG26: =AF26*9.80665/1000 -> 0.20593965 | AH26: =AG26*23.1/100 -> 0.047572059
B27: 11 | C27: 0.0936 | D27: 156 | E27: =D27*0.6 -> 93.6 | F27: =(2*PI()/60)*E27 -> 9.8017691 | W27: indices | AC27: 21 | AD27: 25.3 | AE27: =AD27/5 -> 5.06 | AF27: 22 | AG27: =AF27*9.80665/1000 -> 0.2157463 | AH27: =AG27*23.1/100 -> 0.049837395
B28: 12 | C28: 0.1264 | D28: 209.9 | E28: =D28*0.6 -> 125.94 | F28: =(2*PI()/60)*E28 -> 13.188406 | W28: Bm | X28: =SLOPE(Z7:Z23,V7:V23) -> 4.484906e-06 | AC28: 22 | AD28: 25.9 | AE28: =AD28/5 -> 5.18 | AF28: 23 | AG28: =AF28*9.80665/1000 -> 0.22555295 | AH28: =AG28*23.1/100 -> 0.052102731 | AJ28: a | AK28: =SLOPE(AH7:AH80,AE7:AE80) -> 0.0097374748
B29: 13 | C29: 0.1399 | D29: 231 | E29: =D29*0.6 -> 138.6 | F29: =(2*PI()/60)*E29 -> 14.514158 | W29: Tc | X29: =INTERCEPT(Z7:Z23,V7:V23) -> 0.0066833966 | AC29: 23 | AD29: 28.2 | AE29: =AD29/5 -> 5.64 | AF29: 24 | AG29: =AF29*9.80665/1000 -> 0.2353596 | AH29: =AG29*23.1/100 -> 0.054368068 | AJ29: b | AK29: =INTERCEPT(AH7:AH80,AE7:AE80) -> -0.00048042522
B30: 14 | C30: 0.1642 | D30: 275.9 | E30: =D30*0.6 -> 165.54 | F30: =(2*PI()/60)*E30 -> 17.335308 | H30: RPM | K30: rad/s | AC30: 24 | AD30: 29.5 | AE30: =AD30/5 -> 5.9 | AF30: 25 | AG30: =AF30*9.80665/1000 -> 0.24516625 | AH30: =AG30*23.1/100 -> 0.056633404
B31: 15 | C31: 0.1865 | D31: 312.5 | E31: =D31*0.6 -> 187.5 | F31: =(2*PI()/60)*E31 -> 19.634954 | H31: a | I31: =SLOPE(C16:C66,E16:E66) -> 0.00099800143 | K31: a | L31: =SLOPE(C16:C66,F16:F66) -> 0.0095302116 | W31: τ_mec [ms] | X31: 34.4 | AC31: 25 | AD31: 29.9 | AE31: =AD31/5 -> 5.98 | AF31: 26 | AG31: =AF31*9.80665/1000 -> 0.2549729 | AH31: =AG31*23.1/100 -> 0.05889874
B32: 16 | C32: 0.1974 | D32: 342 | E32: =D32*0.6 -> 205.2 | F32: =(2*PI()/60)*E32 -> 21.488494 | H32: b | I32: =INTERCEPT(C16:C66,E16:E66) -> 1.1973976e-05 | K32: b | L32: =INTERCEPT(C16:C66,F16:F66) -> 1.1973976e-05 | W32: Jm [N·m·s/rad] | X32: =(X31/1000)*(X28+(AL6*AL7/L7)) -> 2.0344826e-05 | Y32: (partida) | AC32: 26 | AD32: 31.3 | AE32: =AD32/5 -> 6.26 | AF32: 27 | AG32: =AF32*9.80665/1000 -> 0.26477955 | AH32: =AG32*23.1/100 -> 0.061164076
B33: 17 | C33: 0.2176 | D33: 359.7 | E33: =D33*0.6 -> 215.82 | F33: =(2*PI()/60)*E33 -> 22.600618 | AC33: 27 | AD33: 32.7 | AE33: =AD33/5 -> 6.54 | AF33: 28 | AG33: =AF33*9.80665/1000 -> 0.2745862 | AH33: =AG33*23.1/100 -> 0.063429412
B34: 18 | C34: 0.2373 | D34: 393 | E34: =D34*0.6 -> 235.8 | F34: =(2*PI()/60)*E34 -> 24.692918 | AC34: 28 | AD34: 33.8 | AE34: =AD34/5 -> 6.76 | AF34: 29 | AG34: =AF34*9.80665/1000 -> 0.28439285 | AH34: =AG34*23.1/100 -> 0.065694748
B35: 19 | C35: 0.2373 | D35: 400.6 | E35: =D35*0.6 -> 240.36 | F35: =(2*PI()/60)*E35 -> 25.17044 | AC35: 29 | AD35: 34.2 | AE35: =AD35/5 -> 6.84 | AF35: 30 | AG35: =AF35*9.80665/1000 -> 0.2941995 | AH35: =AG35*23.1/100 -> 0.067960085
B36: 20 | C36: 0.2514 | D36: 421.5 | E36: =D36*0.6 -> 252.9 | F36: =(2*PI()/60)*E36 -> 26.483626 | AC36: 30 | AD36: 35.4 | AE36: =AD36/5 -> 7.08 | AF36: 31 | AG36: =AF36*9.80665/1000 -> 0.30400615 | AH36: =AG36*23.1/100 -> 0.070225421
B37: 21 | C37: 0.2597 | D37: 425.8 | E37: =D37*0.6 -> 255.48 | F37: =(2*PI()/60)*E37 -> 26.753803 | AC37: 31 | AD37: 37.3 | AE37: =AD37/5 -> 7.46 | AF37: 32 | AG37: =AF37*9.80665/1000 -> 0.3138128 | AH37: =AG37*23.1/100 -> 0.072490757
B38: 22 | C38: 0.2749 | D38: 456.2 | E38: =D38*0.6 -> 273.72 | F38: =(2*PI()/60)*E38 -> 28.663891 | AC38: 32 | AD38: 38.7 | AE38: =AD38/5 -> 7.74 | AF38: 33 | AG38: =AF38*9.80665/1000 -> 0.32361945 | AH38: =AG38*23.1/100 -> 0.074756093
B39: 23 | C39: 0.275 | D39: 462.5 | E39: =D39*0.6 -> 277.5 | F39: =(2*PI()/60)*E39 -> 29.059732 | AC39: 33 | AD39: 40.2 | AE39: =AD39/5 -> 8.04 | AF39: 34 | AG39: =AF39*9.80665/1000 -> 0.3334261 | AH39: =AG39*23.1/100 -> 0.077021429
B40: 24 | C40: 0.2799 | D40: 463.8 | E40: =D40*0.6 -> 278.28 | F40: =(2*PI()/60)*E40 -> 29.141413 | AC40: 34 | AD40: 40.8 | AE40: =AD40/5 -> 8.16 | AF40: 35 | AG40: =AF40*9.80665/1000 -> 0.34323275 | AH40: =AG40*23.1/100 -> 0.079286765
B41: 25 | C41: 0.2971 | D41: 492.6 | E41: =D41*0.6 -> 295.56 | F41: =(2*PI()/60)*E41 -> 30.950971 | AC41: 35 | AD41: 42.5 | AE41: =AD41/5 -> 8.5 | AF41: 36 | AG41: =AF41*9.80665/1000 -> 0.3530394 | AH41: =AG41*23.1/100 -> 0.081552101
B42: 26 | C42: 0.2963 | D42: 495 | E42: =D42*0.6 -> 297 | F42: =(2*PI()/60)*E42 -> 31.101767 | AC42: 36 | AD42: 42.7 | AE42: =AD42/5 -> 8.54 | AF42: 37 | AG42: =AF42*9.80665/1000 -> 0.36284605 | AH42: =AG42*23.1/100 -> 0.083817438
...

Sheet LM2917M-8
H4: Corrente [mA]
D5: Tensão de alimentação [V] | E5: Tensão com zener interno [V] | F5: I drop [mA] | H5: Rdrop | I5: Consumo do CI | J5: Zener | Q5: CI LM297N-8 (Linearidade real) | AD5: CI LM297N-8 (Linearidade real)
D6: 12 | E6: 7.56 | F6: =(D6-E6)*1000/E8 -> 9.4468085 | H6: =F6 -> 9.4468085 | I6: 3,8 a 6 | J6: 3.5 a 5.6 | Q6: Medição | R6: f [Hz] | S6: Vout [V] | T6: Medição | U6: f [Hz] | V6: Vout [V] | W6: Medição | X6: f [Hz] | Y6: Vout [V] | AD6: Medição | AE6: f [Hz] | AF6: Vout [V] | AG6: RPM | AH6: rad/s | AI6: K
Q7: 1 | R7: 200 | S7: 0.0463 | T7: 16 | U7: 6200 | V7: 1.368 | W7: 31 | X7: 13000 | Y7: 2.845 | AD7: 1 | AE7: 0 | AF7: 0 | AG7: =AE7*0.6 -> 0 | AH7: =(AG7*2*PI())/60 -> 0 | AI7: =AF7/($J$41*$K$41*$L$41*AE7) -> #DIV/0!
D8: Rdrop [ohm] = | E8: 470 | H8: Potência do resistor [mW] | Q8: 2 | R8: 600 | S8: 0.1362 | T8: 17 | U8: 6600 | V8: 1.455 | W8: 32 | X8: 13500 | Y8: 2.953 | AD8: 2 | AE8: 200 | AF8: 0.0463 | AG8: =AE8*0.6 -> 120 | AH8: =(AG8*2*PI())/60 -> 12.566371 | AI8: =AF8/($J$41*$K$41*$L$41*AE8) -> 0.94293127
D9: Frequência máxima [kHz] = | E9: 20 | H9: =((D6-E6)^2)*1000/E8 -> 41.94383 | Q9: 3 | R9: 1000 | S9: 0.2259 | T9: 18 | U9: 7000 | V9: 1.542 | W9: 33 | X9: 14000 | Y9: 3.062 | AD9: 3 | AE9: 400 | AF9: 0.0914 | AG9: =AE9*0.6 -> 240 | AH9: =(AG9*2*PI())/60 -> 25.132741 | AI9: =AF9/($J$41*$K$41*$L$41*AE9) -> 0.93071186
Q10: 4 | R10: 1400 | S10: 0.3145 | T10: 19 | U10: 7400 | V10: 1.625 | W10: 34 | X10: 14500 | Y10: 3.17 | AD10: 4 | AE10: 600 | AF10: 0.1362 | AG10: =AE10*0.6 -> 360 | AH10: =(AG10*2*PI())/60 -> 37.699112 | AI10: =AF10/($J$41*$K$41*$L$41*AE10) -> 0.92460216
D11: Parâmetros desejados na saída | Q11: 5 | R11: 1800 | S11: 0.4036 | T11: 20 | U11: 7800 | V11: 1.716 | W11: 35 | X11: 15000 | Y11: 3.279 | AD11: 5 | AE11: 800 | AF11: 0.1811 | AG11: =AE11*0.6 -> 480 | AH11: =(AG11*2*PI())/60 -> 50.265482 | AI11: =AF11/($J$41*$K$41*$L$41*AE11) -> 0.92205645
D12: Tensão máxima na saída | E12: 5 | Q12: 6 | R12: 2200 | S12: 0.4919 | T12: 21 | U12: 8200 | V12: 1.803 | W12: 36 | X12: 15500 | Y12: 3.387 | AD12: 6 | AE12: 1000 | AF12: 0.2259 | AG12: =AE12*0.6 -> 600 | AH12: =(AG12*2*PI())/60 -> 62.831853 | AI12: =AF12/($J$41*$K$41*$L$41*AE12) -> 0.92012171
Q13: 7 | R13: 2600 | S13: 0.5805 | T13: 22 | U13: 8600 | V13: 1.89 | W13: 37 | X13: 16000 | Y13: 3.495 | AD13: 7 | AE13: 1200 | AF13: 0.2704 | AG13: =AE13*0.6 -> 720 | AH13: =(AG13*2*PI())/60 -> 75.398224 | AI13: =AF13/($J$41*$K$41*$L$41*AE13) -> 0.91781359
Q14: 8 | R14: 3000 | S14: 0.668 | T14: 23 | U14: 9000 | V14: 1.978 | W14: 38 | X14: 16500 | Y14: 3.603 | AD14: 8 | AE14: 1400 | AF14: 0.3145 | AG14: =AE14*0.6 -> 840 | AH14: =(AG14*2*PI())/60 -> 87.964594 | AI14: =AF14/($J$41*$K$41*$L$41*AE14) -> 0.91500119
Q15: 9 | R15: 3400 | S15: 0.756 | T15: 24 | U15: 9400 | V15: 2.065 | W15: 39 | X15: 17000 | Y15: 3.712 | AD15: 9 | AE15: 1600 | AF15: 0.3593 | AG15: =AE15*0.6 -> 960 | AH15: =(AG15*2*PI())/60 -> 100.53096 | AI15: =AF15/($J$41*$K$41*$L$41*AE15) -> 0.91467388
D16: K = | E16: 0.9 | Q16: 10 | R16: 3800 | S16: 0.844 | T16: 25 | U16: 10000 | V16: 2.195 | W16: 40 | X16: 17500 | Y16: 3.819 | AD16: 10 | AE16: 1800 | AF16: 0.4036 | AG16: =AE16*0.6 -> 1080 | AH16: =(AG16*2*PI())/60 -> 113.09734 | AI16: =AF16/($J$41*$K$41*$L$41*AE16) -> 0.91328789
D17: C1xR1 [s] = | E17: =E12/(E6*(E9*1000)*E16) -> 3.6743092e-05 | Q17: 11 | R17: 4200 | S17: 0.932 | T17: 26 | U17: 10500 | V17: 2.304 | W17: 41 | X17: 18000 | Y17: 3.927 | AD17: 11 | AE17: 2000 | AF17: 0.4477 | AG17: =AE17*0.6 -> 1200 | AH17: =(AG17*2*PI())/60 -> 125.66371 | AI17: =AF17/($J$41*$K$41*$L$41*AE17) -> 0.91177177
Q18: 12 | R18: 4600 | S18: 1.019 | T18: 27 | U18: 11000 | V18: 2.412 | W18: 42 | X18: 18500 | Y18: 4.036 | AD18: 12 | AE18: 2200 | AF18: 0.4919 | AG18: =AE18*0.6 -> 1320 | AH18: =(AG18*2*PI())/60 -> 138.23008 | AI18: =AF18/($J$41*$K$41*$L$41*AE18) -> 0.91071646
Q19: 13 | R19: 5000 | S19: 1.107 | T19: 28 | U19: 11500 | V19: 2.521 | W19: 43 | X19: 19000 | Y19: 4.144 | AD19: 13 | AE19: 2400 | AF19: 0.536 | AG19: =AE19*0.6 -> 1440 | AH19: =(AG19*2*PI())/60 -> 150.79645 | AI19: =AF19/($J$41*$K$41*$L$41*AE19) -> 0.90966732
Q20: 14 | R20: 5400 | S20: 1.194 | T20: 29 | U20: 12000 | V20: 2.629 | W20: 44 | X20: 19500 | Y20: 4.252 | AD20: 14 | AE20: 2600 | AF20: 0.5805 | AG20: =AE20*0.6 -> 1560 | AH20: =(AG20*2*PI())/60 -> 163.36282 | AI20: =AF20/($J$41*$K$41*$L$41*AE20) -> 0.90940622
Q21: 15 | R21: 5800 | S21: 1.281 | T21: 30 | U21: 12500 | V21: 2.737 | W21: 45 | X21: 20000 | Y21: 4.337 | AD21: 15 | AE21: 2800 | AF21: 0.624 | AG21: =AE21*0.6 -> 1680 | AH21: =(AG21*2*PI())/60 -> 175.92919 | AI21: =AF21/($J$41*$K$41*$L$41*AE21) -> 0.90772773
AD22: 16 | AE22: 3000 | AF22: 0.668 | AG22: =AE22*0.6 -> 1800 | AH22: =(AG22*2*PI())/60 -> 188.49556 | AI22: =AF22/($J$41*$K$41*$L$41*AE22) -> 0.90695189
AD23: 17 | AE23: 3200 | AF23: 0.712 | AG23: =AE23*0.6 -> 1920 | AH23: =(AG23*2*PI())/60 -> 201.06193 | AI23: =AF23/($J$41*$K$41*$L$41*AE23) -> 0.90627304
AD24: 18 | AE24: 3400 | AF24: 0.756 | AG24: =AE24*0.6 -> 2040 | AH24: =(AG24*2*PI())/60 -> 213.6283 | AI24: =AF24/($J$41*$K$41*$L$41*AE24) -> 0.90567405
AD25: 19 | AE25: 3600 | AF25: 0.8 | AG25: =AE25*0.6 -> 2160 | AH25: =(AG25*2*PI())/60 -> 226.19467 | AI25: =AF25/($J$41*$K$41*$L$41*AE25) -> 0.90514161
AD26: 20 | AE26: 3800 | AF26: 0.844 | AG26: =AE26*0.6 -> 2280 | AH26: =(AG26*2*PI())/60 -> 238.76104 | AI26: =AF26/($J$41*$K$41*$L$41*AE26) -> 0.90466522
AD27: 21 | AE27: 4000 | AF27: 0.888 | AG27: =AE27*0.6 -> 2400 | AH27: =(AG27*2*PI())/60 -> 251.32741 | AI27: =AF27/($J$41*$K$41*$L$41*AE27) -> 0.90423647
AD28: 22 | AE28: 4200 | AF28: 0.932 | AG28: =AE28*0.6 -> 2520 | AH28: =(AG28*2*PI())/60 -> 263.89378 | AI28: =AF28/($J$41*$K$41*$L$41*AE28) -> 0.90384855
D29: C1 [F] = | E29: =(1.5*10^(-9))/2 -> 7.5e-10 | G29: Freqência máxima [Hz]: | AD29: 23 | AE29: 4400 | AF29: 0.976 | AG29: =AE29*0.6 -> 2640 | AH29: =(AG29*2*PI())/60 -> 276.46015 | AI29: =AF29/($J$41*$K$41*$L$41*AE29) -> 0.9034959
D30: R1 [ohm] ~= | E30: =E17/E29 -> 48990.79 | G30: I2 = 180uA (tipico) | H30: =(0.00018)/(E29*E6) -> 31746.032 | AD30: 24 | AE30: 4600 | AF30: 1.019 | AG30: =AE30*0.6 -> 2760 | AH30: =(AG30*2*PI())/60 -> 289.02652 | AI30: =AF30/($J$41*$K$41*$L$41*AE30) -> 0.90228845
D31: R1 disponivel [ohm]= | E31: 43300 | G31: I2 = 140uA (pior caso) | H31: =(0.00014)/(E29*E6) -> 24691.358 | AD31: 25 | AE31: 4800 | AF31: 1.063 | AG31: =AE31*0.6 -> 2880 | AH31: =(AG31*2*PI())/60 -> 301.59289 | AI31: =AF31/($J$41*$K$41*$L$41*AE31) -> 0.90203019
AD32: 26 | AE32: 5000 | AF32: 1.107 | AG32: =AE32*0.6 -> 3000 | AH32: =(AG32*2*PI())/60 -> 314.15927 | AI32: =AF32/($J$41*$K$41*$L$41*AE32) -> 0.90179259
D33: C2 [F] = | E33: =100*10^(-9) -> 1e-07 | G33: Verificação da limitação por corrente de saída: | AD33: 27 | AE33: 5200 | AF33: 1.15 | AG33: =AE33*0.6 -> 3120 | AH33: =(AG33*2*PI())/60 -> 326.72564 | AI33: =AF33/($J$41*$K$41*$L$41*AE33) -> 0.90078997
G34: I3 = 180uA (tipico) | H34: =(0.00018)*E31 -> 7.794 | I34: =_xlfn.CONCAT("> ",E35) -> > 4,419198 | AD34: 28 | AE34: 5400 | AF34: 1.194 | AG34: =AE34*0.6 -> 3240 | AH34: =(AG34*2*PI())/60 -> 339.29201 | AI34: =AF34/($J$41*$K$41*$L$41*AE34) -> 0.9006159
D35: Vout [V] = | E35: =E6*(1000*E9)*E29*E31*E16 -> 4.419198 | G35: I3 = 140uA (pior caso) | H35: =(0.00014)*E31 -> 6.062 | I35: =_xlfn.CONCAT("> ",E35) -> > 4,419198 | AD35: 29 | AE35: 5600 | AF35: 1.238 | AG35: =AE35*0.6 -> 3360 | AH35: =(AG35*2*PI())/60 -> 351.85838 | AI35: =AF35/($J$41*$K$41*$L$41*AE35) -> 0.90045427
AD36: 30 | AE36: 5800 | AF36: 1.281 | AG36: =AE36*0.6 -> 3480 | AH36: =(AG36*2*PI())/60 -> 364.42475 | AI36: =AF36/($J$41*$K$41*$L$41*AE36) -> 0.89960152
D37: Sensicilidade [V/kHz] = | E37: =E35/(E9) -> 0.2209599 | AD37: 31 | AE37: 6000 | AF37: 1.325 | AG37: =AE37*0.6 -> 3600 | AH37: =(AG37*2*PI())/60 -> 376.99112 | AI37: =AF37/($J$41*$K$41*$L$41*AE37) -> 0.89948448
AD38: 32 | AE38: 6200 | AF38: 1.368 | AG38: =AE38*0.6 -> 3720 | AH38: =(AG38*2*PI())/60 -> 389.55749 | AI38: =AF38/($J$41*$K$41*$L$41*AE38) -> 0.89871803
AD39: 33 | AE39: 6400 | AF39: 1.412 | AG39: =AE39*0.6 -> 3840 | AH39: =(AG39*2*PI())/60 -> 402.12386 | AI39: =AF39/($J$41*$K$41*$L$41*AE39) -> 0.89863591
AD40: 34 | AE40: 6600 | AF40: 1.455 | AG40: =AE40*0.6 -> 3960 | AH40: =(AG40*2*PI())/60 -> 414.69023 | AI40: =AF40/($J$41*$K$41*$L$41*AE40) -> 0.89794162
H41: 4.337 | I41: 20000 | J41: 7.56 | K41: 7.5e-10 | L41: 43300 | N41: =J41*K41*L41*0.9 -> 0.0002209599 | AD41: 35 | AE41: 6800 | AF41: 1.498 | AG41: =AE41*0.6 -> 4080 | AH41: =(AG41*2*PI())/60 -> 427.2566 | AI41: =AF41/($J$41*$K$41*$L$41*AE41) -> 0.89728818
AD42: 36 | AE42: 7000 | AF42: 1.542 | AG42: =AE42*0.6 -> 4200 | AH42: =(AG42*2*PI())/60 -> 439.82297 | AI42: =AF42/($J$41*$K$41*$L$41*AE42) -> 0.89725395
D43: Vripple = | E43: =(E6/2)*(E29/E33)*(1-((E6*E9*1000*E29)/0.00018)) -> 0.0104895 | H43: =H41/(I41*J41*K41*L41) -> 0.88325981 | AD43: 37 | AE43: 7200 | AF43: 1.585 | AG43: =AE43*0.6 -> 4320 | AH43: =(AG43*2*PI())/60 -> 452.38934 | AI43: =AF43/($J$41*$K$41*$L$41*AE43) -> 0.89665591
...

Sheet SG3525
C2: CT [nF] = | E2: 1 | F2: CT [nF] = | H2: 2 | I2: CT [nF] = | K2: 5 | L2: CT [µF] = | N2: 0.01 | O2: CT [µF] = | Q2: 0.02 | R2: CT [µF] = | T2: 0.05 | U2: CT [µF] = | W2: 0.1
C3: Tempo [µs] | D3: RT [kΩ] | E3: t/CT | F3: Tempo [µs] | G3: RT [kΩ] | H3: t/CT | I3: Tempo [µs] | J3: RT [kΩ] | K3: t/CT | L3: Tempo [µs] | M3: RT [kΩ] | N3: t/CT | O3: Tempo [µs] | P3: RT [kΩ] | Q3: t/CT | R3: Tempo [µs] | S3: RT [kΩ] | T3: t/CT | U3: Tempo [µs] | V3: RT [kΩ] | W3: t/CT
C4: 2.0645 | D4: 1.9758 | E4: =(C4*0.000001)/($E$2*0.000000001) -> 2064.5 | F4: 3.42949 | G4: 2 | H4: =(F4*0.000001)/($H$2*0.000000001) -> 1714.745 | I4: 7.82377 | J4: 2 | K4: =(I4*0.000001)/($K$2*0.000000001) -> 1564.754 | L4: 16.2283 | M4: 1.97585 | N4: =(L4*0.000001)/($N$2*0.000001) -> 1622.83 | O4: 33.1317 | P4: 2 | Q4: =(O4*0.000001)/($Q$2*0.000001) -> 1656.585 | R4: 72.0719 | S4: 2 | T4: =(R4*0.000001)/($T$2*0.000001) -> 1441.438 | U4: 154.312 | V4: 2 | W4: =(U4*0.000001)/($W$2*0.000001) -> 1543.12 | AA4: CT [nF] = | AC4: 1 | AD4: CT [nF] = | AF4: 2 | AG4: CT [nF] = | AI4: 5 | AJ4: CT [µF] = | AL4: 0.01
C5: 16.228 | D5: 18.936 | E5: =(C5*0.000001)/($E$2*0.000000001) -> 16228 | F5: 29.1835 | G5: 17.6044 | H5: =(F5*0.000001)/($H$2*0.000000001) -> 14591.75 | I5: 66.5771 | J5: 19.1673 | K5: =(I5*0.000001)/($K$2*0.000000001) -> 13315.42 | L5: 125.561 | M5: 15.9737 | N5: =(L5*0.000001)/($N$2*0.000001) -> 12556.1 | O5: 295.677 | P5: 18.0374 | Q5: =(O5*0.000001)/($Q$2*0.000001) -> 14783.85 | R5: 707.406 | S5: 19.6388 | T5: =(R5*0.000001)/($T$2*0.000001) -> 14148.12 | U5: 1156.65 | V5: 15.9737 | W5: =(U5*0.000001)/($W$2*0.000001) -> 11566.5 | AA5: Tempo [µs] | AB5: RT [kΩ] | AC5: t/CT | AD5: Tempo [µs] | AE5: RT [kΩ] | AF5: t/CT | AG5: Tempo [µs] | AH5: RT [kΩ] | AI5: t/CT | AJ5: Tempo [µs] | AK5: RT [kΩ] | AL5: t/CT
C6: 108.86 | D6: 151.24 | E6: =(C6*0.000001)/($E$2*0.000000001) -> 108860 | F6: 244.432 | G6: 151.237 | H6: =(F6*0.000001)/($H$2*0.000000001) -> 122216 | I6: 468.355 | J6: 151.237 | K6: =(I6*0.000001)/($K$2*0.000000001) -> 93671 | L6: 1138.45 | M6: 151.237 | N6: =(L6*0.000001)/($N$2*0.000001) -> 113845 | O6: 2437.53 | P6: 149.41 | Q6: =(O6*0.000001)/($Q$2*0.000001) -> 121876.5 | R6: 5473.28 | S6: 151.237 | T6: =(R6*0.000001)/($T$2*0.000001) -> 109465.6 | U6: 10159.9 | V6: 151.237 | W6: =(U6*0.000001)/($W$2*0.000001) -> 101599 | AA6: 2.0645 | AB6: 1.9758 | AC6: =(AA6*0.000001)/($E$2*0.000000001) -> 2064.5 | AD6: 3.42949 | AE6: 2 | AF6: =(AD6*0.000001)/($H$2*0.000000001) -> 1714.745 | AG6: 7.82377 | AH6: 2 | AI6: =(AG6*0.000001)/($K$2*0.000000001) -> 1564.754 | AJ6: 16.2283 | AK6: 1.97585 | AL6: =(AJ6*0.000001)/($N$2*0.000001) -> 1622.83
AA7: 16.228 | AB7: 18.936 | AC7: =(AA7*0.000001)/($E$2*0.000000001) -> 16228 | AD7: 29.1835 | AE7: 17.6044 | AF7: =(AD7*0.000001)/($H$2*0.000000001) -> 14591.75 | AG7: 66.5771 | AH7: 19.1673 | AI7: =(AG7*0.000001)/($K$2*0.000000001) -> 13315.42 | AJ7: 125.561 | AK7: 15.9737 | AL7: =(AJ7*0.000001)/($N$2*0.000001) -> 12556.1
B8: inclinação | C8: =SLOPE(E4:E6,D4:D6)/1000 -> 0.70963985 | F8: =SLOPE(H4:H6,G4:G6)/1000 -> 0.8066384 | I8: =SLOPE(K4:K6,J4:J6)/1000 -> 0.613863 | L8: =SLOPE(N4:N6,M4:M6)/1000 -> 0.75063477 | O8: =SLOPE(Q4:Q6,P4:P6)/1000 -> 0.81540684 | R8: =SLOPE(T4:T6,S4:S6)/1000 -> 0.72401736 | U8: =SLOPE(W4:W6,V4:V6)/1000 -> 0.66850145 | AA8: 108.86 | AB8: 151.24 | AC8: =(AA8*0.000001)/($E$2*0.000000001) -> 108860 | AD8: 244.432 | AE8: 151.237 | AF8: =(AD8*0.000001)/($H$2*0.000000001) -> 122216 | AG8: 468.355 | AH8: 151.237 | AI8: =(AG8*0.000001)/($K$2*0.000000001) -> 93671 | AJ8: 1138.45 | AK8: 151.237 | AL8: =(AJ8*0.000001)/($N$2*0.000001) -> 113845
B9: intercessão | C9: =INTERCEPT(E4:E6,D4:D6)/1000 -> 1.6622409 | F9: =INTERCEPT(H4:H6,G4:G6)/1000 -> 0.23842056 | I9: =INTERCEPT(K4:K6,J4:J6)/1000 -> 0.9061845 | L9: =INTERCEPT(N4:N6,M4:M6)/1000 -> 0.34220791 | O9: =INTERCEPT(Q4:Q6,P4:P6)/1000 -> 0.049455375 | R9: =INTERCEPT(T4:T6,S4:S6)/1000 -> -0.036640967 | U9: =INTERCEPT(W4:W6,V4:V6)/1000 -> 0.53034038 | AA9: CT [µF] = | AC9: 0.02 | AD9: CT [µF] = | AF9: 0.05 | AG9: CT [µF] = | AI9: 0.1
B10: media | C10: =SUM(C8,F8,I8,L8,O8,R8,U8)/7 -> 0.72695738 | AA10: Tempo [µs] | AB10: RT [kΩ] | AC10: t/CT | AD10: Tempo [µs] | AE10: RT [kΩ] | AF10: t/CT | AG10: Tempo [µs] | AH10: RT [kΩ] | AI10: t/CT
AA11: 33.1317 | AB11: 2 | AC11: =(AA11*0.000001)/($Q$2*0.000001) -> 1656.585 | AD11: 72.0719 | AE11: 2 | AF11: =(AD11*0.000001)/($T$2*0.000001) -> 1441.438 | AG11: 154.312 | AH11: 2 | AI11: =(AG11*0.000001)/($W$2*0.000001) -> 1543.12
AA12: 295.677 | AB12: 18.0374 | AC12: =(AA12*0.000001)/($Q$2*0.000001) -> 14783.85 | AD12: 707.406 | AE12: 19.6388 | AF12: =(AD12*0.000001)/($T$2*0.000001) -> 14148.12 | AG12: 1156.65 | AH12: 15.9737 | AI12: =(AG12*0.000001)/($W$2*0.000001) -> 11566.5
AA13: 2437.53 | AB13: 149.41 | AC13: =(AA13*0.000001)/($Q$2*0.000001) -> 121876.5 | AD13: 5473.28 | AE13: 151.237 | AF13: =(AD13*0.000001)/($T$2*0.000001) -> 109465.6 | AG13: 10159.9 | AH13: 151.237 | AI13: =(AG13*0.000001)/($W$2*0.000001) -> 101599
AC17: CT | AD17: m | AE17: média
AC18: 1 nF | AD18: =SLOPE(E4:E6,D4:D6)/1000 -> 0.70963985 | AE18: =SUM(AD18:AD24)/7 -> 0.72695738
AC19: 2 nF | AD19: =SLOPE(H4:H6,G4:G6)/1000 -> 0.8066384
AC20: 5 nF | AD20: =SLOPE(K4:K6,J4:J6)/1000 -> 0.613863
AC21: 0,01 µF | AD21: =SLOPE(N4:N6,M4:M6)/1000 -> 0.75063477
AC22: 0,02µF | AD22: =SLOPE(Q4:Q6,P4:P6)/1000 -> 0.81540684
AC23: 0,05 µF | AD23: =SLOPE(T4:T6,S4:S6)/1000 -> 0.72401736
AC24: 0,1 µF | AD24: =SLOPE(W4:W6,V4:V6)/1000 -> 0.66850145

Sheet Jm
C2: =J104 -> 2.1291097e-05
B3: inicial | F3: Tempo | G3: w | H3: RPM
B4: 12000 | C4: =(B4*2*PI())/60 -> 1256.6371 | E4: 0 | F4: 0 | G4: =C4 -> 1256.6371 | H4: =(G4*60)/(2*PI()) -> 12000 | I4: =IF(F4-($F$12+($B$8/120))<0,0,F4-($F$12+($B$8/120))) -> 0 | L4: =(-Ensaios!X28*Jm!F114)/(LN((Ensaios!X29/Ensaios!X28)/(Jm!G14+(Ensaios!X29/Ensaios!X28)))) -> 2.7202881e-05
E5: 1 | F5: =F4+($B$8/120) -> 0.033333333 | G5: =IF(($C$4+(Ensaios!$X$29/Ensaios!$X$28))*(EXP((-Ensaios!$X$28/$C$2)*(IF(F5-($F$12+($B$8/120))<0,0,F5-($F$12+($B$8/120))))))-(Ensaios!$X$29/Ensaios!$X$28)>0,($C$4+(Ensaios!$X$29/Ensaios!$X$28))*(EXP((-Ensaios!$X$28/$C$2)*(IF(F5-($F$12+($B$8/120))<0,0,F5-($F$12+($B$8/120))))))-(Ensaios!$X$29/Ensaios!$X$28),0) -> 1256.6371 | H5: =(G5*60)/(2*PI()) -> 12000 | I5: =IF(F5-($F$12+($B$8/120))<0,0,F5-($F$12+($B$8/120))) -> 0
E6: 2 | F6: =F5+($B$8/120) -> 0.066666667 | G6: =IF(($C$4+(Ensaios!$X$29/Ensaios!$X$28))*(EXP((-Ensaios!$X$28/$C$2)*(IF(F6-($F$12+($B$8/120))<0,0,F6-($F$12+($B$8/120))))))-(Ensaios!$X$29/Ensaios!$X$28)>0,($C$4+(Ensaios!$X$29/Ensaios!$X$28))*(EXP((-Ensaios!$X$28/$C$2)*(IF(F6-($F$12+($B$8/120))<0,0,F6-($F$12+($B$8/120))))))-(Ensaios!$X$29/Ensaios!$X$28),0) -> 1256.6371 | H6: =(G6*60)/(2*PI()) -> 12000 | I6: =IF(F6-($F$12+($B$8/120))<0,0,F6-($F$12+($B$8/120))) -> 0
B7: TEMPO TOTAL | E7: 3 | F7: =F6+($B$8/120) -> 0.1 | G7: =IF(($C$4+(Ensaios!$X$29/Ensaios!$X$28))*(EXP((-Ensaios!$X$28/$C$2)*(IF(F7-($F$12+($B$8/120))<0,0,F7-($F$12+($B$8/120))))))-(Ensaios!$X$29/Ensaios!$X$28)>0,($C$4+(Ensaios!$X$29/Ensaios!$X$28))*(EXP((-Ensaios!$X$28/$C$2)*(IF(F7-($F$12+($B$8/120))<0,0,F7-($F$12+($B$8/120))))))-(Ensaios!$X$29/Ensaios!$X$28),0) -> 1256.6371 | H7: =(G7*60)/(2*PI()) -> 12000 | I7: =IF(F7-($F$12+($B$8/120))<0,0,F7-($F$12+($B$8/120))) -> 0
B8: 4 | E8: 4 | F8: =F7+($B$8/120) -> 0.13333333 | G8: =IF(($C$4+(Ensaios!$X$29/Ensaios!$X$28))*(EXP((-Ensaios!$X$28/$C$2)*(IF(F8-($F$12+($B$8/120))<0,0,F8-($F$12+($B$8/120))))))-(Ensaios!$X$29/Ensaios!$X$28)>0,($C$4+(Ensaios!$X$29/Ensaios!$X$28))*(EXP((-Ensaios!$X$28/$C$2)*(IF(F8-($F$12+($B$8/120))<0,0,F8-($F$12+($B$8/120))))))-(Ensaios!$X$29/Ensaios!$X$28),0) -> 1256.6371 | H8: =(G8*60)/(2*PI()) -> 12000 | I8: =IF(F8-($F$12+($B$8/120))<0,0,F8-($F$12+($B$8/120))) -> 0
E9: 5 | F9: =F8+($B$8/120) -> 0.16666667 | G9: =IF(($C$4+(Ensaios!$X$29/Ensaios!$X$28))*(EXP((-Ensaios!$X$28/$C$2)*(IF(F9-($F$12+($B$8/120))<0,0,F9-($F$12+($B$8/120))))))-(Ensaios!$X$29/Ensaios!$X$28)>0,($C$4+(Ensaios!$X$29/Ensaios!$X$28))*(EXP((-Ensaios!$X$28/$C$2)*(IF(F9-($F$12+($B$8/120))<0,0,F9-($F$12+($B$8/120))))))-(Ensaios!$X$29/Ensaios!$X$28),0) -> 1256.6371 | H9: =(G9*60)/(2*PI()) -> 12000 | I9: =IF(F9-($F$12+($B$8/120))<0,0,F9-($F$12+($B$8/120))) -> 0
E10: 6 | F10: =F9+($B$8/120) -> 0.2 | G10: =IF(($C$4+(Ensaios!$X$29/Ensaios!$X$28))*(EXP((-Ensaios!$X$28/$C$2)*(IF(F10-($F$12+($B$8/120))<0,0,F10-($F$12+($B$8/120))))))-(Ensaios!$X$29/Ensaios!$X$28)>0,($C$4+(Ensaios!$X$29/Ensaios!$X$28))*(EXP((-Ensaios!$X$28/$C$2)*(IF(F10-($F$12+($B$8/120))<0,0,F10-($F$12+($B$8/120))))))-(Ensaios!$X$29/Ensaios!$X$28),0) -> 1256.6371 | H10: =(G10*60)/(2*PI()) -> 12000 | I10: =IF(F10-($F$12+($B$8/120))<0,0,F10-($F$12+($B$8/120))) -> 0
E11: 7 | F11: =F10+($B$8/120) -> 0.23333333 | G11: =IF(($C$4+(Ensaios!$X$29/Ensaios!$X$28))*(EXP((-Ensaios!$X$28/$C$2)*(IF(F11-($F$12+($B$8/120))<0,0,F11-($F$12+($B$8/120))))))-(Ensaios!$X$29/Ensaios!$X$28)>0,($C$4+(Ensaios!$X$29/Ensaios!$X$28))*(EXP((-Ensaios!$X$28/$C$2)*(IF(F11-($F$12+($B$8/120))<0,0,F11-($F$12+($B$8/120))))))-(Ensaios!$X$29/Ensaios!$X$28),0) -> 1256.6371 | H11: =(G11*60)/(2*PI()) -> 12000 | I11: =IF(F11-($F$12+($B$8/120))<0,0,F11-($F$12+($B$8/120))) -> 0
E12: 8 | F12: =F11+($B$8/120) -> 0.26666667 | G12: =IF(($C$4+(Ensaios!$X$29/Ensaios!$X$28))*(EXP((-Ensaios!$X$28/$C$2)*(IF(F12-($F$12+($B$8/120))<0,0,F12-($F$12+($B$8/120))))))-(Ensaios!$X$29/Ensaios!$X$28)>0,($C$4+(Ensaios!$X$29/Ensaios!$X$28))*(EXP((-Ensaios!$X$28/$C$2)*(IF(F12-($F$12+($B$8/120))<0,0,F12-($F$12+($B$8/120))))))-(Ensaios!$X$29/Ensaios!$X$28),0) -> 1256.6371 | H12: =(G12*60)/(2*PI()) -> 12000 | I12: =IF(F12-($F$12+($B$8/120))<0,0,F12-($F$12+($B$8/120))) -> 0
E13: 9 | F13: =F12+($B$8/120) -> 0.3 | G13: =IF(($C$4+(Ensaios!$X$29/Ensaios!$X$28))*(EXP((-Ensaios!$X$28/$C$2)*(IF(F13-($F$12+($B$8/120))<0,0,F13-($F$12+($B$8/120))))))-(Ensaios!$X$29/Ensaios!$X$28)>0,($C$4+(Ensaios!$X$29/Ensaios!$X$28))*(EXP((-Ensaios!$X$28/$C$2)*(IF(F13-($F$12+($B$8/120))<0,0,F13-($F$12+($B$8/120))))))-(Ensaios!$X$29/Ensaios!$X$28),0) -> 1256.6371 | H13: =(G13*60)/(2*PI()) -> 12000 | I13: =IF(F13-($F$12+($B$8/120))<0,0,F13-($F$12+($B$8/120))) -> 0
E14: 10 | F14: =F13+($B$8/120) -> 0.33333333 | G14: =IF(($C$4+(Ensaios!$X$29/Ensaios!$X$28))*(EXP((-Ensaios!$X$28/$C$2)*(IF(F14-($F$12+($B$8/120))<0,0,F14-($F$12+($B$8/120))))))-(Ensaios!$X$29/Ensaios!$X$28)>0,($C$4+(Ensaios!$X$29/Ensaios!$X$28))*(EXP((-Ensaios!$X$28/$C$2)*(IF(F14-($F$12+($B$8/120))<0,0,F14-($F$12+($B$8/120))))))-(Ensaios!$X$29/Ensaios!$X$28),0) -> 1237.4175 | H14: =(G14*60)/(2*PI()) -> 11816.467
E15: 11 | F15: =F14+($B$8/120) -> 0.36666667 | G15: =IF(($C$4+(Ensaios!$X$29/Ensaios!$X$28))*(EXP((-Ensaios!$X$28/$C$2)*(IF(F15-($F$12+($B$8/120))<0,0,F15-($F$12+($B$8/120))))))-(Ensaios!$X$29/Ensaios!$X$28)>0,($C$4+(Ensaios!$X$29/Ensaios!$X$28))*(EXP((-Ensaios!$X$28/$C$2)*(IF(F15-($F$12+($B$8/120))<0,0,F15-($F$12+($B$8/120))))))-(Ensaios!$X$29/Ensaios!$X$28),0) -> 1218.3325 | H15: =(G15*60)/(2*PI()) -> 11634.218 | I15: =IF(F15-($F$12+($B$8/120))<0,0,F15-($F$12+($B$8/120))) -> 0.066666667
E16: 12 | F16: =F15+($B$8/120) -> 0.4 | G16: =IF(($C$4+(Ensaios!$X$29/Ensaios!$X$28))*(EXP((-Ensaios!$X$28/$C$2)*(IF(F16-($F$12+($B$8/120))<0,0,F16-($F$12+($B$8/120))))))-(Ensaios!$X$29/Ensaios!$X$28)>0,($C$4+(Ensaios!$X$29/Ensaios!$X$28))*(EXP((-Ensaios!$X$28/$C$2)*(IF(F16-($F$12+($B$8/120))<0,0,F16-($F$12+($B$8/120))))))-(Ensaios!$X$29/Ensaios!$X$28),0) -> 1199.381 | H16: =(G16*60)/(2*PI()) -> 11453.245 | I16: =IF(F16-($F$12+($B$8/120))<0,0,F16-($F$12+($B$8/120))) -> 0.1
E17: 13 | F17: =F16+($B$8/120) -> 0.43333333 | G17: =IF(($C$4+(Ensaios!$X$29/Ensaios!$X$28))*(EXP((-Ensaios!$X$28/$C$2)*(IF(F17-($F$12+($B$8/120))<0,0,F17-($F$12+($B$8/120))))))-(Ensaios!$X$29/Ensaios!$X$28)>0,($C$4+(Ensaios!$X$29/Ensaios!$X$28))*(EXP((-Ensaios!$X$28/$C$2)*(IF(F17-($F$12+($B$8/120))<0,0,F17-($F$12+($B$8/120))))))-(Ensaios!$X$29/Ensaios!$X$28),0) -> 1180.5621 | H17: =(G17*60)/(2*PI()) -> 11273.537 | I17: =IF(F17-($F$12+($B$8/120))<0,0,F17-($F$12+($B$8/120))) -> 0.13333333
E18: 14 | F18: =F17+($B$8/120) -> 0.46666667 | G18: =IF(($C$4+(Ensaios!$X$29/Ensaios!$X$28))*(EXP((-Ensaios!$X$28/$C$2)*(IF(F18-($F$12+($B$8/120))<0,0,F18-($F$12+($B$8/120))))))-(Ensaios!$X$29/Ensaios!$X$28)>0,($C$4+(Ensaios!$X$29/Ensaios!$X$28))*(EXP((-Ensaios!$X$28/$C$2)*(IF(F18-($F$12+($B$8/120))<0,0,F18-($F$12+($B$8/120))))))-(Ensaios!$X$29/Ensaios!$X$28),0) -> 1161.8748 | H18: =(G18*60)/(2*PI()) -> 11095.087 | I18: =IF(F18-($F$12+($B$8/120))<0,0,F18-($F$12+($B$8/120))) -> 0.16666667
E19: 15 | F19: =F18+($B$8/120) -> 0.5 | G19: =IF(($C$4+(Ensaios!$X$29/Ensaios!$X$28))*(EXP((-Ensaios!$X$28/$C$2)*(IF(F19-($F$12+($B$8/120))<0,0,F19-($F$12+($B$8/120))))))-(Ensaios!$X$29/Ensaios!$X$28)>0,($C$4+(Ensaios!$X$29/Ensaios!$X$28))*(EXP((-Ensaios!$X$28/$C$2)*(IF(F19-($F$12+($B$8/120))<0,0,F19-($F$12+($B$8/120))))))-(Ensaios!$X$29/Ensaios!$X$28),0) -> 1143.3183 | H19: =(G19*60)/(2*PI()) -> 10917.886 | I19: =IF(F19-($F$12+($B$8/120))<0,0,F19-($F$12+($B$8/120))) -> 0.2
E20: 16 | F20: =F19+($B$8/120) -> 0.53333333 | G20: =IF(($C$4+(Ensaios!$X$29/Ensaios!$X$28))*(EXP((-Ensaios!$X$28/$C$2)*(IF(F20-($F$12+($B$8/120))<0,0,F20-($F$12+($B$8/120))))))-(Ensaios!$X$29/Ensaios!$X$28)>0,($C$4+(Ensaios!$X$29/Ensaios!$X$28))*(EXP((-Ensaios!$X$28/$C$2)*(IF(F20-($F$12+($B$8/120))<0,0,F20-($F$12+($B$8/120))))))-(Ensaios!$X$29/Ensaios!$X$28),0) -> 1124.8917 | H20: =(G20*60)/(2*PI()) -> 10741.924 | I20: =IF(F20-($F$12+($B$8/120))<0,0,F20-($F$12+($B$8/120))) -> 0.23333333
E21: 17 | F21: =F20+($B$8/120) -> 0.56666667 | G21: =IF(($C$4+(Ensaios!$X$29/Ensaios!$X$28))*(EXP((-Ensaios!$X$28/$C$2)*(IF(F21-($F$12+($B$8/120))<0,0,F21-($F$12+($B$8/120))))))-(Ensaios!$X$29/Ensaios!$X$28)>0,($C$4+(Ensaios!$X$29/Ensaios!$X$28))*(EXP((-Ensaios!$X$28/$C$2)*(IF(F21-($F$12+($B$8/120))<0,0,F21-($F$12+($B$8/120))))))-(Ensaios!$X$29/Ensaios!$X$28),0) -> 1106.594 | H21: =(G21*60)/(2*PI()) -> 10567.194 | I21: =IF(F21-($F$12+($B$8/120))<0,0,F21-($F$12+($B$8/120))) -> 0.26666667
E22: 18 | F22: =F21+($B$8/120) -> 0.6 | G22: =IF(($C$4+(Ensaios!$X$29/Ensaios!$X$28))*(EXP((-Ensaios!$X$28/$C$2)*(IF(F22-($F$12+($B$8/120))<0,0,F22-($F$12+($B$8/120))))))-(Ensaios!$X$29/Ensaios!$X$28)>0,($C$4+(Ensaios!$X$29/Ensaios!$X$28))*(EXP((-Ensaios!$X$28/$C$2)*(IF(F22-($F$12+($B$8/120))<0,0,F22-($F$12+($B$8/120))))))-(Ensaios!$X$29/Ensaios!$X$28),0) -> 1088.4243 | H22: =(G22*60)/(2*PI()) -> 10393.686 | I22: =IF(F22-($F$12+($B$8/120))<0,0,F22-($F$12+($B$8/120))) -> 0.3
E23: 19 | F23: =F22+($B$8/120) -> 0.63333333 | G23: =IF(($C$4+(Ensaios!$X$29/Ensaios!$X$28))*(EXP((-Ensaios!$X$28/$C$2)*(IF(F23-($F$12+($B$8/120))<0,0,F23-($F$12+($B$8/120))))))-(Ensaios!$X$29/Ensaios!$X$28)>0,($C$4+(Ensaios!$X$29/Ensaios!$X$28))*(EXP((-Ensaios!$X$28/$C$2)*(IF(F23-($F$12+($B$8/120))<0,0,F23-($F$12+($B$8/120))))))-(Ensaios!$X$29/Ensaios!$X$28),0) -> 1070.3818 | H23: =(G23*60)/(2*PI()) -> 10221.393 | I23: =IF(F23-($F$12+($B$8/120))<0,0,F23-($F$12+($B$8/120))) -> 0.33333333
E24: 20 | F24: =F23+($B$8/120) -> 0.66666667 | G24: =IF(($C$4+(Ensaios!$X$29/Ensaios!$X$28))*(EXP((-Ensaios!$X$28/$C$2)*(IF(F24-($F$12+($B$8/120))<0,0,F24-($F$12+($B$8/120))))))-(Ensaios!$X$29/Ensaios!$X$28)>0,($C$4+(Ensaios!$X$29/Ensaios!$X$28))*(EXP((-Ensaios!$X$28/$C$2)*(IF(F24-($F$12+($B$8/120))<0,0,F24-($F$12+($B$8/120))))))-(Ensaios!$X$29/Ensaios!$X$28),0) -> 1052.4654 | H24: =(G24*60)/(2*PI()) -> 10050.305 | I24: =IF(F24-($F$12+($B$8/120))<0,0,F24-($F$12+($B$8/120))) -> 0.36666667
E25: 21 | F25: =F24+($B$8/120) -> 0.7 | G25: =IF(($C$4+(Ensaios!$X$29/Ensaios!$X$28))*(EXP((-Ensaios!$X$28/$C$2)*(IF(F25-($F$12+($B$8/120))<0,0,F25-($F$12+($B$8/120))))))-(Ensaios!$X$29/Ensaios!$X$28)>0,($C$4+(Ensaios!$X$29/Ensaios!$X$28))*(EXP((-Ensaios!$X$28/$C$2)*(IF(F25-($F$12+($B$8/120))<0,0,F25-($F$12+($B$8/120))))))-(Ensaios!$X$29/Ensaios!$X$28),0) -> 1034.6745 | H25: =(G25*60)/(2*PI()) -> 9880.4137 | I25: =IF(F25-($F$12+($B$8/120))<0,0,F25-($F$12+($B$8/120))) -> 0.4
E26: 22 | F26: =F25+($B$8/120) -> 0.73333333 | G26: =IF(($C$4+(Ensaios!$X$29/Ensaios!$X$28))*(EXP((-Ensaios!$X$28/$C$2)*(IF(F26-($F$12+($B$8/120))<0,0,F26-($F$12+($B$8/120))))))-(Ensaios!$X$29/Ensaios!$X$28)>0,($C$4+(Ensaios!$X$29/Ensaios!$X$28))*(EXP((-Ensaios!$X$28/$C$2)*(IF(F26-($F$12+($B$8/120))<0,0,F26-($F$12+($B$8/120))))))-(Ensaios!$X$29/Ensaios!$X$28),0) -> 1017.008 | H26: =(G26*60)/(2*PI()) -> 9711.7114 | I26: =IF(F26-($F$12+($B$8/120))<0,0,F26-($F$12+($B$8/120))) -> 0.43333333
... E103: 99 | F103: =F102+($B$8/120) -> 3.3 | G103: =IF(($C$4+(Ensaios!$X$29/Ensaios!$X$28))*(EXP((-Ensaios!$X$28/$C$2)*(IF(F103-($F$12+($B$8/120))<0,0,F103-($F$12+($B$8/120))))))-(Ensaios!$X$29/Ensaios!$X$28)>0,($C$4+(Ensaios!$X$29/Ensaios!$X$28))*(EXP((-Ensaios!$X$28/$C$2)*(IF(F103-($F$12+($B$8/120))<0,0,F103-($F$12+($B$8/120))))))-(Ensaios!$X$29/Ensaios!$X$28),0) -> 0 | H103: =(G103*60)/(2*PI()) -> 0 | I103: =IF(F103-($F$12+($B$8/120))<0,0,F103-($F$12+($B$8/120))) -> 3
E104: 100 | F104: =F103+($B$8/120) -> 3.3333333 | G104: =IF(($C$4+(Ensaios!$X$29/Ensaios!$X$28))*(EXP((-Ensaios!$X$28/$C$2)*(IF(F104-($F$12+($B$8/120))<0,0,F104-($F$12+($B$8/120))))))-(Ensaios!$X$29/Ensaios!$X$28)>0,($C$4+(Ensaios!$X$29/Ensaios!$X$28))*(EXP((-Ensaios!$X$28/$C$2)*(IF(F104-($F$12+($B$8/120))<0,0,F104-($F$12+($B$8/120))))))-(Ensaios!$X$29/Ensaios!$X$28),0) -> 0 | H104: =(G104*60)/(2*PI()) -> 0 | I104: =IF(F104-($F$12+($B$8/120))<0,0,F104-($F$12+($B$8/120))) -> 3.0333333 | J104: 2.1291097e-05 | K104: 3.6904568e-05
E105: 101 | F105: =F104+($B$8/120) -> 3.3666667 | G105: =IF(($C$4+(Ensaios!$X$29/Ensaios!$X$28))*(EXP((-Ensaios!$X$28/$C$2)*(IF(F105-($F$12+($B$8/120))<0,0,F105-($F$12+($B$8/120))))))-(Ensaios!$X$29/Ensaios!$X$28)>0,($C$4+(Ensaios!$X$29/Ensaios!$X$28))*(EXP((-Ensaios!$X$28/$C$2)*(IF(F105-($F$12+($B$8/120))<0,0,F105-($F$12+($B$8/120))))))-(Ensaios!$X$29/Ensaios!$X$28),0) -> 0 | H105: =(G105*60)/(2*PI()) -> 0 | I105: =IF(F105-($F$12+($B$8/120))<0,0,F105-($F$12+($B$8/120))) -> 3.0666667
E106: 102 | F106: =F105+($B$8/120) -> 3.4 | G106: =IF(($C$4+(Ensaios!$X$29/Ensaios!$X$28))*(EXP((-Ensaios!$X$28/$C$2)*(IF(F106-($F$12+($B$8/120))<0,0,F106-($F$12+($B$8/120))))))-(Ensaios!$X$29/Ensaios!$X$28)>0,($C$4+(Ensaios!$X$29/Ensaios!$X$28))*(EXP((-Ensaios!$X$28/$C$2)*(IF(F106-($F$12+($B$8/120))<0,0,F106-($F$12+($B$8/120))))))-(Ensaios!$X$29/Ensaios!$X$28),0) -> 0 | H106: =(G106*60)/(2*PI()) -> 0 | I106: =IF(F106-($F$12+($B$8/120))<0,0,F106-($F$12+($B$8/120))) -> 3.1
E107: 103 | F107: =F106+($B$8/120) -> 3.4333333 | G107: =IF(($C$4+(Ensaios!$X$29/Ensaios!$X$28))*(EXP((-Ensaios!$X$28/$C$2)*(IF(F107-($F$12+($B$8/120))<0,0,F107-($F$12+($B$8/120))))))-(Ensaios!$X$29/Ensaios!$X$28)>0,($C$4+(Ensaios!$X$29/Ensaios!$X$28))*(EXP((-Ensaios!$X$28/$C$2)*(IF(F107-($F$12+($B$8/120))<0,0,F107-($F$12+($B$8/120))))))-(Ensaios!$X$29/Ensaios!$X$28),0) -> 0 | H107: =(G107*60)/(2*PI()) -> 0 | I107: =IF(F107-($F$12+($B$8/120))<0,0,F107-($F$12+($B$8/120))) -> 3.1333333
E108: 104 | F108: =F107+($B$8/120) -> 3.4666667 | G108: =IF(($C$4+(Ensaios!$X$29/Ensaios!$X$28))*(EXP((-Ensaios!$X$28/$C$2)*(IF(F108-($F$12+($B$8/120))<0,0,F108-($F$12+($B$8/120))))))-(Ensaios!$X$29/Ensaios!$X$28)>0,($C$4+(Ensaios!$X$29/Ensaios!$X$28))*(EXP((-Ensaios!$X$28/$C$2)*(IF(F108-($F$12+($B$8/120))<0,0,F108-($F$12+($B$8/120))))))-(Ensaios!$X$29/Ensaios!$X$28),0) -> 0 | H108: =(G108*60)/(2*PI()) -> 0 | I108: =IF(F108-($F$12+($B$8/120))<0,0,F108-($F$12+($B$8/120))) -> 3.1666667
E109: 105 | F109: =F108+($B$8/120) -> 3.5 | G109: =IF(($C$4+(Ensaios!$X$29/Ensaios!$X$28))*(EXP((-Ensaios!$X$28/$C$2)*(IF(F109-($F$12+($B$8/120))<0,0,F109-($F$12+($B$8/120))))))-(Ensaios!$X$29/Ensaios!$X$28)>0,($C$4+(Ensaios!$X$29/Ensaios!$X$28))*(EXP((-Ensaios!$X$28/$C$2)*(IF(F109-($F$12+($B$8/120))<0,0,F109-($F$12+($B$8/120))))))-(Ensaios!$X$29/Ensaios!$X$28),0) -> 0 | H109: =(G109*60)/(2*PI()) -> 0 | I109: =IF(F109-($F$12+($B$8/120))<0,0,F109-($F$12+($B$8/120))) -> 3.2
E110: 106 | F110: =F109+($B$8/120) -> 3.5333333 | G110: =IF(($C$4+(Ensaios!$X$29/Ensaios!$X$28))*(EXP((-Ensaios!$X$28/$C$2)*(IF(F110-($F$12+($B$8/120))<0,0,F110-($F$12+($B$8/120))))))-(Ensaios!$X$29/Ensaios!$X$28)>0,($C$4+(Ensaios!$X$29/Ensaios!$X$28))*(EXP((-Ensaios!$X$28/$C$2)*(IF(F110-($F$12+($B$8/120))<0,0,F110-($F$12+($B$8/120))))))-(Ensaios!$X$29/Ensaios!$X$28),0) -> 0 | H110: =(G110*60)/(2*PI()) -> 0 | I110: =IF(F110-($F$12+($B$8/120))<0,0,F110-($F$12+($B$8/120))) -> 3.2333333
E111: 107 | F111: =F110+($B$8/120) -> 3.5666667 | G111: =IF(($C$4+(Ensaios!$X$29/Ensaios!$X$28))*(EXP((-Ensaios!$X$28/$C$2)*(IF(F111-($F$12+($B$8/120))<0,0,F111-($F$12+($B$8/120))))))-(Ensaios!$X$29/Ensaios!$X$28)>0,($C$4+(Ensaios!$X$29/Ensaios!$X$28))*(EXP((-Ensaios!$X$28/$C$2)*(IF(F111-($F$12+($B$8/120))<0,0,F111-($F$12+($B$8/120))))))-(Ensaios!$X$29/Ensaios!$X$28),0) -> 0 | H111: =(G111*60)/(2*PI()) -> 0 | I111: =IF(F111-($F$12+($B$8/120))<0,0,F111-($F$12+($B$8/120))) -> 3.2666667
E112: 108 | F112: =F111+($B$8/120) -> 3.6 | G112: =IF(($C$4+(Ensaios!$X$29/Ensaios!$X$28))*(EXP((-Ensaios!$X$28/$C$2)*(IF(F112-($F$12+($B$8/120))<0,0,F112-($F$12+($B$8/120))))))-(Ensaios!$X$29/Ensaios!$X$28)>0,($C$4+(Ensaios!$X$29/Ensaios!$X$28))*(EXP((-Ensaios!$X$28/$C$2)*(IF(F112-($F$12+($B$8/120))<0,0,F112-($F$12+($B$8/120))))))-(Ensaios!$X$29/Ensaios!$X$28),0) -> 0 | H112: =(G112*60)/(2*PI()) -> 0 | I112: =IF(F112-($F$12+($B$8/120))<0,0,F112-($F$12+($B$8/120))) -> 3.3
E113: 109 | F113: =F112+($B$8/120) -> 3.6333333 | G113: =IF(($C$4+(Ensaios!$X$29/Ensaios!$X$28))*(EXP((-Ensaios!$X$28/$C$2)*(IF(F113-($F$12+($B$8/120))<0,0,F113-($F$12+($B$8/120))))))-(Ensaios!$X$29/Ensaios!$X$28)>0,($C$4+(Ensaios!$X$29/Ensaios!$X$28))*(EXP((-Ensaios!$X$28/$C$2)*(IF(F113-($F$12+($B$8/120))<0,0,F113-($F$12+($B$8/120))))))-(Ensaios!$X$29/Ensaios!$X$28),0) -> 0 | H113: =(G113*60)/(2*PI()) -> 0 | I113: =IF(F113-($F$12+($B$8/120))<0,0,F113-($F$12+($B$8/120))) -> 3.3333333
E114: 110 | F114: =F113+($B$8/120) -> 3.6666667 | G114: =IF(($C$4+(Ensaios!$X$29/Ensaios!$X$28))*(EXP((-Ensaios!$X$28/$C$2)*(IF(F114-($F$12+($B$8/120))<0,0,F114-($F$12+($B$8/120))))))-(Ensaios!$X$29/Ensaios!$X$28)>0,($C$4+(Ensaios!$X$29/Ensaios!$X$28))*(EXP((-Ensaios!$X$28/$C$2)*(IF(F114-($F$12+($B$8/120))<0,0,F114-($F$12+($B$8/120))))))-(Ensaios!$X$29/Ensaios!$X$28),0) -> 0 | H114: =(G114*60)/(2*PI()) -> 0 | I114: =IF(F114-($F$12+($B$8/120))<0,0,F114-($F$12+($B$8/120))) -> 3.3666667
E115: 111 | F115: =F114+($B$8/120) -> 3.7 | G115: =IF(($C$4+(Ensaios!$X$29/Ensaios!$X$28))*(EXP((-Ensaios!$X$28/$C$2)*(IF(F115-($F$12+($B$8/120))<0,0,F115-($F$12+($B$8/120))))))-(Ensaios!$X$29/Ensaios!$X$28)>0,($C$4+(Ensaios!$X$29/Ensaios!$X$28))*(EXP((-Ensaios!$X$28/$C$2)*(IF(F115-($F$12+($B$8/120))<0,0,F115-($F$12+($B$8/120))))))-(Ensaios!$X$29/Ensaios!$X$28),0) -> 0 | H115: =(G115*60)/(2*PI()) -> 0 | I115: =IF(F115-($F$12+($B$8/120))<0,0,F115-($F$12+($B$8/120))) -> 3.4
E116: 112 | F116: =F115+($B$8/120) -> 3.7333333 | G116: =IF(($C$4+(Ensaios!$X$29/Ensaios!$X$28))*(EXP((-Ensaios!$X$28/$C$2)*(IF(F116-($F$12+($B$8/120))<0,0,F116-($F$12+($B$8/120))))))-(Ensaios!$X$29/Ensaios!$X$28)>0,($C$4+(Ensaios!$X$29/Ensaios!$X$28))*(EXP((-Ensaios!$X$28/$C$2)*(IF(F116-($F$12+($B$8/120))<0,0,F116-($F$12+($B$8/120))))))-(Ensaios!$X$29/Ensaios!$X$28),0) -> 0 | H116: =(G116*60)/(2*PI()) -> 0 | I116: =IF(F116-($F$12+($B$8/120))<0,0,F116-($F$12+($B$8/120))) -> 3.4333333
... E124: 120 | F124: =F123+($B$8/120) -> 4 | G124: =IF(($C$4+(Ensaios!$X$29/Ensaios!$X$28))*(EXP((-Ensaios!$X$28/$C$2)*(IF(F124-($F$12+($B$8/120))<0,0,F124-($F$12+($B$8/120))))))-(Ensaios!$X$29/Ensaios!$X$28)>0,($C$4+(Ensaios!$X$29/Ensaios!$X$28))*(EXP((-Ensaios!$X$28/$C$2)*(IF(F124-($F$12+($B$8/120))<0,0,F124-($F$12+($B$8/120))))))-(Ensaios!$X$29/Ensaios!$X$28),0) -> 0 | H124: =(G124*60)/(2*PI()) -> 0 | I124: =IF(F124-($F$12+($B$8/120))<0,0,F124-($F$12+($B$8/120))) -> 3.7
...

Sheet Planilha3

Sheet Planilha1
B6: ; ; ; corrente de partida; efeito da saturação de corrente.
F8: Degrau | G8: velocidade final atingida | H8: tempo de subida | I8: tempo de acomodação | J8: constante de tempo
E9: Simulação | F9: 12V
E10: Real
E11: Simulação | F11: 500mV
E12: Real

Sheet Planilha1 (2)
B8: A | AA8: A invertido
B14: A atrasado invertido | AA14: A atrasado
B20: A ou A atrasado invertido | AA20: A invertido ou A atrasado
B25: Conresponde a borda de descida | AA25: Conresponde a borda de subida
